<?xml version="1.0" ?>
<!-- =================================================================================== -->
<!-- |    This document was autogenerated by xacro from hyperdog.urdf.xacro            | -->
<!-- |    EDITING THIS FILE BY HAND IS NOT RECOMMENDED                                 | -->
<!-- =================================================================================== -->
<!-- 
__________________________________________________________________________________
MIT License                                                                       |
                                                                                  |
Copyright (c) 2024 W.M. Nipun Dhananjaya Weerakkodi                               |
                                                                                  | 
Permission is hereby granted, free of charge, to any person obtaining a copy      |
of this software and associated documentation files (the "Software"), to deal     |
in the Software without restriction, including without limitation the rights      |
to use, copy, modify, merge, publish, distribute, sublicense, and/or sell         |
copies of the Software, and to permit persons to whom the Software is             |
furnished to do so, subject to the following conditions:                          |
                                                                                  |
The above copyright notice and this permission notice shall be included in all    |
copies or substantial portions of the Software.                                   |
                                                                                  |
THE SOFTWARE IS PROVIDED "AS IS", WITHOUT WARRANTY OF ANY KIND, EXPRESS OR        |
IMPLIED, INCLUDING BUT NOT LIMITED TO THE WARRANTIES OF MERCHANTABILITY,          |
FITNESS FOR A PARTICULAR PURPOSE AND NONINFRINGEMENT. IN NO EVENT SHALL THE       |
AUTHORS OR COPYRIGHT HOLDERS BE LIABLE FOR ANY CLAIM, DAMAGES OR OTHER            |
LIABILITY, WHETHER IN AN ACTION OF CONTRACT, TORT OR OTHERWISE, ARISING FROM,     |
OUT OF OR IN CONNECTION WITH THE SOFTWARE OR THE USE OR OTHER DEALINGS IN THE     |
SOFTWARE.                                                                         |
__________________________________________________________________________________|
 -->
<robot name="hyperdog">
  <!-- ***************  CONFIGURE ROBOT"S LINKS  *******************-->
  <!-- 
    * Autor: nipun.dhananjaya@gmail.com
    * Date:  13.03.2023


    _____________________________________________________________________
        include this file into: /description/hyperdog.urdf.xacro 
        using following line: 
                    <xacro:include filename="hyperdog_urdf_links.xacro" /> 
    _____________________________________________________________________ -->
  <!-- ************************************************************************************************** -->
  <!-- *********** Inertial link *********** -->
  <link name="inertial_link">
    <inertial>
      <origin rpy="0 0 0" xyz="-0.006 0.00633 0.00214"/>
      <!-- 0.006, -0.000233, 0.00214 -->
      <mass value="3"/>
      <inertia ixx="0.011396658109874464" ixy="0" ixz="0" iyy="0.05486450023370329" iyz="0" izz="0.06098759357764758"/>
    </inertial>
  </link>
  <!-- *********** base link *********** -->
  <link name="base_link">
    <visual>
      <origin rpy="0 0 0" xyz="0 0 0"/>
      <geometry>
        <mesh filename="file:///home/vimarsh/Desktop/ROS-Stuff/hyprdog_ws/install/hyperdog_gazebo_sim/share/hyperdog_gazebo_sim/meshes/body.stl" scale="0.001 0.001 0.001"/>
      </geometry>
      <material name="green">
        <color rgba="0.2 1 0.2 1"/>
      </material>
    </visual>
    <collision>
      <origin rpy="0 0 0" xyz="0 0 0"/>
      <geometry>
        <mesh filename="file:///home/vimarsh/Desktop/ROS-Stuff/hyprdog_ws/install/hyperdog_gazebo_sim/share/hyperdog_gazebo_sim/meshes/body.stl" scale="0.001 0.001 0.001"/>
      </geometry>
    </collision>
  </link>
  <!-- !!!!!!!!!!!!!!!!!!!!!!! HIPS !!!!!!!!!!!!!!!!!!!!!!!!!!!! -->
  <!-- *********** FR_hip *********** -->
  <link name="FR_hip_link">
    <visual>
      <origin rpy="0 0 0" xyz="0 0 0"/>
      <geometry>
        <mesh filename="file:///home/vimarsh/Desktop/ROS-Stuff/hyprdog_ws/install/hyperdog_gazebo_sim/share/hyperdog_gazebo_sim/meshes/RIGHT_HIP.stl" scale="0.001 0.001 0.001"/>
      </geometry>
      <material name="red">
        <color rgba="0.8 0.2 0.2 1"/>
      </material>
    </visual>
    <collision>
      <origin rpy="0 0 0" xyz="0 0 0"/>
      <geometry>
        <mesh filename="file:///home/vimarsh/Desktop/ROS-Stuff/hyprdog_ws/install/hyperdog_gazebo_sim/share/hyperdog_gazebo_sim/meshes/RIGHT_HIP.stl" scale="0.001 0.001 0.001"/>
      </geometry>
    </collision>
    <inertial>
      <origin rpy="0 0 0" xyz="0.0 -0.02 0.01"/>
      <mass value="0.3"/>
      <inertia ixx="0.000785664594069212" ixy="0" ixz="0" iyy="0.00028126771524959764" iyz="0" izz="0.0007138119943369485"/>
    </inertial>
  </link>
  <!-- *********** FL_hip ********** -->
  <link name="FL_hip_link">
    <visual>
      <origin rpy="0 0 0" xyz="0 0 0"/>
      <geometry>
        <mesh filename="file:///home/vimarsh/Desktop/ROS-Stuff/hyprdog_ws/install/hyperdog_gazebo_sim/share/hyperdog_gazebo_sim/meshes/LEFT_HIP.stl" scale="0.001 0.001 0.001"/>
      </geometry>
      <material name="red">
        <color rgba="0.8 0.2 0.2 1"/>
      </material>
    </visual>
    <collision>
      <origin rpy="0 0 0" xyz="0 0 0"/>
      <geometry>
        <mesh filename="file:///home/vimarsh/Desktop/ROS-Stuff/hyprdog_ws/install/hyperdog_gazebo_sim/share/hyperdog_gazebo_sim/meshes/LEFT_HIP.stl" scale="0.001 0.001 0.001"/>
      </geometry>
    </collision>
    <inertial>
      <origin rpy="0 0 0" xyz="0.0 0.02 0.01"/>
      <mass value="0.3"/>
      <inertia ixx="0.000785664594069212" ixy="0" ixz="0" iyy="0.00028126771524959764" iyz="0" izz="0.0007138119943369485"/>
    </inertial>
  </link>
  <!-- *********** BR_hip ********** -->
  <link name="BR_hip_link">
    <visual>
      <origin rpy="0 0 0" xyz="0 0 0"/>
      <geometry>
        <mesh filename="file:///home/vimarsh/Desktop/ROS-Stuff/hyprdog_ws/install/hyperdog_gazebo_sim/share/hyperdog_gazebo_sim/meshes/RIGHT_HIP.stl" scale="0.001 0.001 0.001"/>
      </geometry>
      <material name="red">
        <color rgba="0.8 0.2 0.2 1"/>
      </material>
    </visual>
    <collision>
      <origin rpy="0 0 0" xyz="0 0 0"/>
      <geometry>
        <mesh filename="file:///home/vimarsh/Desktop/ROS-Stuff/hyprdog_ws/install/hyperdog_gazebo_sim/share/hyperdog_gazebo_sim/meshes/RIGHT_HIP.stl" scale="0.001 0.001 0.001"/>
      </geometry>
    </collision>
    <inertial>
      <origin rpy="0 0 0" xyz="0.0 -0.02 0.01"/>
      <mass value="0.3"/>
      <inertia ixx="0.000785664594069212" ixy="0" ixz="0" iyy="0.00028126771524959764" iyz="0" izz="0.0007138119943369485"/>
    </inertial>
  </link>
  <!-- *********** BL_hip ********** -->
  <link name="BL_hip_link">
    <visual>
      <origin rpy="0 0 0" xyz="0 0 0"/>
      <geometry>
        <mesh filename="file:///home/vimarsh/Desktop/ROS-Stuff/hyprdog_ws/install/hyperdog_gazebo_sim/share/hyperdog_gazebo_sim/meshes/LEFT_HIP.stl" scale="0.001 0.001 0.001"/>
      </geometry>
      <material name="red">
        <color rgba="0.8 0.2 0.2 1"/>
      </material>
    </visual>
    <collision>
      <origin rpy="0 0 0" xyz="0 0 0"/>
      <geometry>
        <mesh filename="file:///home/vimarsh/Desktop/ROS-Stuff/hyprdog_ws/install/hyperdog_gazebo_sim/share/hyperdog_gazebo_sim/meshes/LEFT_HIP.stl" scale="0.001 0.001 0.001"/>
      </geometry>
    </collision>
    <inertial>
      <origin rpy="0 0 0" xyz="0.0 0.02 0.01"/>
      <mass value="0.3"/>
      <inertia ixx="0.000785664594069212" ixy="0" ixz="0" iyy="0.00028126771524959764" iyz="0" izz="0.0007138119943369485"/>
    </inertial>
  </link>
  <!-- !!!!!!!!!!!!!!!!!!!!!!! ULEGs !!!!!!!!!!!!!!!!!!!!!!!!!!!! -->
  <!-- *********** FR_uleg ********** -->
  <link name="FR_uleg_link">
    <visual>
      <origin rpy="0 0 0" xyz="0 0 0"/>
      <geometry>
        <mesh filename="file:///home/vimarsh/Desktop/ROS-Stuff/hyprdog_ws/install/hyperdog_gazebo_sim/share/hyperdog_gazebo_sim/meshes/RIGHT_ULEG.stl" scale="0.001 0.001 0.001"/>
      </geometry>
      <material name="orange">
        <color rgba="0.8 0.5 0.8 1"/>
      </material>
    </visual>
    <collision>
      <origin rpy="0 0 0" xyz="0 0 0"/>
      <geometry>
        <mesh filename="file:///home/vimarsh/Desktop/ROS-Stuff/hyprdog_ws/install/hyperdog_gazebo_sim/share/hyperdog_gazebo_sim/meshes/RIGHT_ULEG.stl" scale="0.001 0.001 0.001"/>
      </geometry>
    </collision>
    <inertial>
      <origin rpy="0 0 0" xyz="-0.02 0.02 0.0"/>
      <mass value="0.5"/>
      <inertia ixx="0.0005320036781441746" ixy="0" ixz="0" iyy="0.00178632152356757" iyz="0" izz="0.002124721126775121"/>
    </inertial>
  </link>
  <!-- *********** FL_uleg ********** -->
  <link name="FL_uleg_link">
    <visual>
      <origin rpy="0 0 0" xyz="0 0 0"/>
      <geometry>
        <mesh filename="file:///home/vimarsh/Desktop/ROS-Stuff/hyprdog_ws/install/hyperdog_gazebo_sim/share/hyperdog_gazebo_sim/meshes/LEFT_ULEG.stl" scale="0.001 0.001 0.001"/>
      </geometry>
      <material name="orange">
        <color rgba="0.8 0.5 0.8 1"/>
      </material>
    </visual>
    <collision>
      <origin rpy="0 0 0" xyz="0 0 0"/>
      <geometry>
        <mesh filename="file:///home/vimarsh/Desktop/ROS-Stuff/hyprdog_ws/install/hyperdog_gazebo_sim/share/hyperdog_gazebo_sim/meshes/LEFT_ULEG.stl" scale="0.001 0.001 0.001"/>
      </geometry>
    </collision>
    <inertial>
      <origin rpy="0 0 0" xyz="-0.02 -0.02 0.0"/>
      <mass value="0.5"/>
      <inertia ixx="0.0005320036934665719" ixy="0" ixz="0" iyy="0.0017863215388899672" iyz="0" izz="0.002124721126775121"/>
    </inertial>
  </link>
  <!-- *********** BR_uleg ********** -->
  <link name="BR_uleg_link">
    <visual>
      <origin rpy="0 0 0" xyz="0 0 0"/>
      <geometry>
        <mesh filename="file:///home/vimarsh/Desktop/ROS-Stuff/hyprdog_ws/install/hyperdog_gazebo_sim/share/hyperdog_gazebo_sim/meshes/RIGHT_ULEG.stl" scale="0.001 0.001 0.001"/>
      </geometry>
      <material name="orange">
        <color rgba="0.8 0.5 0.8 1"/>
      </material>
    </visual>
    <collision>
      <origin rpy="0 0 0" xyz="0 0 0"/>
      <geometry>
        <mesh filename="file:///home/vimarsh/Desktop/ROS-Stuff/hyprdog_ws/install/hyperdog_gazebo_sim/share/hyperdog_gazebo_sim/meshes/RIGHT_ULEG.stl" scale="0.001 0.001 0.001"/>
      </geometry>
    </collision>
    <inertial>
      <origin rpy="0 0 0" xyz="-0.02 0.02 0.0"/>
      <mass value="0.5"/>
      <inertia ixx="0.0005320036781441746" ixy="0" ixz="0" iyy="0.00178632152356757" iyz="0" izz="0.002124721126775121"/>
    </inertial>
  </link>
  <!-- *********** BL_uleg ********** -->
  <link name="BL_uleg_link">
    <visual>
      <origin rpy="0 0 0" xyz="0 0 0"/>
      <geometry>
        <mesh filename="file:///home/vimarsh/Desktop/ROS-Stuff/hyprdog_ws/install/hyperdog_gazebo_sim/share/hyperdog_gazebo_sim/meshes/LEFT_ULEG.stl" scale="0.001 0.001 0.001"/>
      </geometry>
      <material name="orange">
        <color rgba="0.8 0.5 0.8 1"/>
      </material>
    </visual>
    <collision>
      <origin rpy="0 0 0" xyz="0 0 0"/>
      <geometry>
        <mesh filename="file:///home/vimarsh/Desktop/ROS-Stuff/hyprdog_ws/install/hyperdog_gazebo_sim/share/hyperdog_gazebo_sim/meshes/LEFT_ULEG.stl" scale="0.001 0.001 0.001"/>
      </geometry>
    </collision>
    <inertial>
      <origin rpy="0 0 0" xyz="-0.02 -0.02 0.0"/>
      <mass value="0.5"/>
      <inertia ixx="0.0005320036934665719" ixy="0" ixz="0" iyy="0.0017863215388899672" iyz="0" izz="0.002124721126775121"/>
    </inertial>
  </link>
  <!-- !!!!!!!!!!!!!!!!!!!!!!! LLEGs !!!!!!!!!!!!!!!!!!!!!!!!!!!! -->
  <!-- *********** FR_lleg ********** -->
  <link name="FR_lleg_link">
    <visual>
      <origin rpy="0 0 0" xyz="0 0 0"/>
      <geometry>
        <mesh filename="file:///home/vimarsh/Desktop/ROS-Stuff/hyprdog_ws/install/hyperdog_gazebo_sim/share/hyperdog_gazebo_sim/meshes/LLEG.stl" scale="0.001 0.001 0.001"/>
      </geometry>
      <material name="yellow">
        <color rgba="0.8 1.0 0.1 1"/>
      </material>
    </visual>
    <collision>
      <origin rpy="0 0 0" xyz="0 0 0"/>
      <geometry>
        <mesh filename="file:///home/vimarsh/Desktop/ROS-Stuff/hyprdog_ws/install/hyperdog_gazebo_sim/share/hyperdog_gazebo_sim/meshes/LLEG.stl" scale="0.001 0.001 0.001"/>
      </geometry>
    </collision>
    <inertial>
      <origin rpy="0 0 0" xyz="0.05 0.0 0.0"/>
      <mass value="0.2"/>
      <inertia ixx="6.323427512607013e-05" ixy="0" ixz="0" iyy="0.0006549703843792289" iyz="0" izz="0.0006232548592531587"/>
    </inertial>
  </link>
  <!-- *********** FL_lleg ********** -->
  <link name="FL_lleg_link">
    <visual>
      <origin rpy="0 0 0" xyz="0 0 0"/>
      <geometry>
        <mesh filename="file:///home/vimarsh/Desktop/ROS-Stuff/hyprdog_ws/install/hyperdog_gazebo_sim/share/hyperdog_gazebo_sim/meshes/LLEG.stl" scale="0.001 0.001 0.001"/>
      </geometry>
      <material name="yellow">
        <color rgba="0.8 1.0 0.1 1"/>
      </material>
    </visual>
    <collision>
      <origin rpy="0 0 0" xyz="0 0 0"/>
      <geometry>
        <mesh filename="file:///home/vimarsh/Desktop/ROS-Stuff/hyprdog_ws/install/hyperdog_gazebo_sim/share/hyperdog_gazebo_sim/meshes/LLEG.stl" scale="0.001 0.001 0.001"/>
      </geometry>
    </collision>
    <inertial>
      <origin rpy="0 0 0" xyz="0.05 0.0 0.0"/>
      <mass value="0.2"/>
      <inertia ixx="6.323427512607013e-05" ixy="0" ixz="0" iyy="0.0006549703843792289" iyz="0" izz="0.0006232548592531587"/>
    </inertial>
  </link>
  <!-- *********** BR_lleg ********** -->
  <link name="BR_lleg_link">
    <visual>
      <origin rpy="0 0 0" xyz="0 0 0"/>
      <geometry>
        <mesh filename="file:///home/vimarsh/Desktop/ROS-Stuff/hyprdog_ws/install/hyperdog_gazebo_sim/share/hyperdog_gazebo_sim/meshes/LLEG.stl" scale="0.001 0.001 0.001"/>
      </geometry>
      <material name="yellow">
        <color rgba="0.8 1.0 0.1 1"/>
      </material>
    </visual>
    <collision>
      <origin rpy="0 0 0" xyz="0 0 0"/>
      <geometry>
        <mesh filename="file:///home/vimarsh/Desktop/ROS-Stuff/hyprdog_ws/install/hyperdog_gazebo_sim/share/hyperdog_gazebo_sim/meshes/LLEG.stl" scale="0.001 0.001 0.001"/>
      </geometry>
    </collision>
    <inertial>
      <origin rpy="0 0 0" xyz="0.05 0.0 0.0"/>
      <mass value="0.2"/>
      <inertia ixx="6.323427512607013e-05" ixy="0" ixz="0" iyy="0.0006549703843792289" iyz="0" izz="0.0006232548592531587"/>
    </inertial>
  </link>
  <!-- *********** BL_lleg ********** -->
  <link name="BL_lleg_link">
    <visual>
      <origin rpy="0 0 0" xyz="0 0 0"/>
      <geometry>
        <mesh filename="file:///home/vimarsh/Desktop/ROS-Stuff/hyprdog_ws/install/hyperdog_gazebo_sim/share/hyperdog_gazebo_sim/meshes/LLEG.stl" scale="0.001 0.001 0.001"/>
      </geometry>
      <material name="yellow">
        <color rgba="0.8 1.0 0.1 1"/>
      </material>
    </visual>
    <collision>
      <origin rpy="0 0 0" xyz="0 0 0"/>
      <geometry>
        <mesh filename="file:///home/vimarsh/Desktop/ROS-Stuff/hyprdog_ws/install/hyperdog_gazebo_sim/share/hyperdog_gazebo_sim/meshes/LLEG.stl" scale="0.001 0.001 0.001"/>
      </geometry>
    </collision>
    <inertial>
      <origin rpy="0 0 0" xyz="0.05 0.0 0.0"/>
      <mass value="0.2"/>
      <inertia ixx="6.323427512607013e-05" ixy="0" ixz="0" iyy="0.0006549703843792289" iyz="0" izz="0.0006232548592531587"/>
    </inertial>
  </link>
  <!-- !!!!!!!!!!!!!!!!!!!!!!! FEET !!!!!!!!!!!!!!!!!!!!!!!!!!!! -->
  <!-- *********** FL FOOT ********** -->
  <link name="FL_foot">
    <visual>
      <origin rpy="0 0 0" xyz="0 0 0"/>
      <geometry>
        <sphere radius="0.02"/>
      </geometry>
      <material name="orange"/>
    </visual>
    <collision>
      <origin rpy="0 0 0" xyz="0 0 0"/>
      <geometry>
        <sphere radius="0.02"/>
      </geometry>
      <surface>
        <friction>
          <ode>
            <mu>1</mu>
            <mu2>1</mu2>
            <fdir1>1 0 0</fdir1>
          </ode>
        </friction>
      </surface>
    </collision>
    <inertial>
      <origin rpy="0 0 0" xyz="0.0 0.0 0.0"/>
      <mass value="0.1"/>
      <inertia ixx="1.6666666666666667e-06" ixy="0.0" ixz="0.0" iyy="1.6666666666666667e-06" iyz="0.0" izz="1.6666666666666667e-06"/>
    </inertial>
  </link>
  <!-- *********** FR FOOT ********** -->
  <link name="FR_foot">
    <visual>
      <origin rpy="0 0 0" xyz="0 0 0"/>
      <geometry>
        <sphere radius="0.02"/>
      </geometry>
      <material name="orange"/>
    </visual>
    <collision>
      <origin rpy="0 0 0" xyz="0 0 0"/>
      <geometry>
        <sphere radius="0.02"/>
      </geometry>
      <surface>
        <friction>
          <ode>
            <mu>1</mu>
            <mu2>1</mu2>
            <fdir1>1 0 0</fdir1>
          </ode>
        </friction>
      </surface>
    </collision>
    <inertial>
      <origin rpy="0 0 0" xyz="0.0 0.0 0.0"/>
      <mass value="0.1"/>
      <inertia ixx="1.6666666666666667e-06" ixy="0.0" ixz="0.0" iyy="1.6666666666666667e-06" iyz="0.0" izz="1.6666666666666667e-06"/>
    </inertial>
  </link>
  <!-- *********** BR FOOT ********** -->
  <link name="BR_foot">
    <visual>
      <origin rpy="0 0 0" xyz="0 0 0"/>
      <geometry>
        <sphere radius="0.02"/>
      </geometry>
      <material name="orange"/>
    </visual>
    <collision>
      <origin rpy="0 0 0" xyz="0 0 0"/>
      <geometry>
        <sphere radius="0.02"/>
      </geometry>
      <surface>
        <friction>
          <ode>
            <mu>1</mu>
            <mu2>1</mu2>
            <fdir1>1 0 0</fdir1>
          </ode>
        </friction>
      </surface>
    </collision>
    <inertial>
      <origin rpy="0 0 0" xyz="0.0 0.0 0.0"/>
      <mass value="0.1"/>
      <inertia ixx="1.6666666666666667e-06" ixy="0.0" ixz="0.0" iyy="1.6666666666666667e-06" iyz="0.0" izz="1.6666666666666667e-06"/>
    </inertial>
  </link>
  <!-- *********** BL FOOT ********** -->
  <link name="BL_foot">
    <visual>
      <origin rpy="0 0 0" xyz="0.0 0 0"/>
      <geometry>
        <sphere radius="0.02"/>
      </geometry>
      <material name="orange"/>
    </visual>
    <collision>
      <origin rpy="0 0 0" xyz="0 0 0"/>
      <geometry>
        <sphere radius="0.02"/>
      </geometry>
      <surface>
        <friction>
          <ode>
            <mu>1</mu>
            <mu2>1</mu2>
            <fdir1>1 0 0</fdir1>
          </ode>
        </friction>
      </surface>
    </collision>
    <inertial>
      <origin rpy="0 0 0" xyz="0.0 0.0 0.0"/>
      <mass value="0.1"/>
      <inertia ixx="1.6666666666666667e-06" ixy="0.0" ixz="0.0" iyy="1.6666666666666667e-06" iyz="0.0" izz="1.6666666666666667e-06"/>
    </inertial>
  </link>
  <!-- 
    _____________________________________________________________________
        include this file into: /description/hyperdog.urdf.xacro 
        using following line: 
                    <xacro:include filename="hyperdog_urdf_joints.xacro" /> 
    _____________________________________________________________________ -->
  <!-- ******** Inertial-base joint ********** -->
  <joint name="inertial_joint" type="fixed">
    <parent link="base_link"/>
    <child link="inertial_link"/>
  </joint>
  <!-- *********  FR_hip joint ********* -->
  <joint name="FR_hip_joint" type="revolute">
    <axis xyz="-1 0 0"/>
    <origin rpy="0 0 0" xyz="0.175 -0.066 0"/>
    <parent link="base_link"/>
    <child link="FR_hip_link"/>
    <limit effort="10" lower="-1.57" upper="1.57" velocity="1"/>
    <!-- effort = 7 -->
    <dynamics damping="0.01" friction="10000"/>
  </joint>
  <!-- *********  FL_hip  ********* -->
  <joint name="FL_hip_joint" type="revolute">
    <axis xyz="1 0 0"/>
    <origin rpy="0 0 0" xyz="0.175 0.066 0"/>
    <parent link="base_link"/>
    <child link="FL_hip_link"/>
    <limit effort="10" lower="-1.57" upper="1.57" velocity="1"/>
    <!-- effort = 7 -->
    <dynamics damping="0.01" friction="10000"/>
  </joint>
  <!-- *********  BR_hip  ********* -->
  <joint name="BR_hip_joint" type="revolute">
    <axis xyz="-1 0 0"/>
    <origin rpy="0 0 0" xyz="-0.175 -0.066 0"/>
    <parent link="base_link"/>
    <child link="BR_hip_link"/>
    <limit effort="10" lower="-1.57" upper="1.57" velocity="1"/>
    <!-- effort = 7 -->
    <dynamics damping="0.01" friction="10000"/>
  </joint>
  <!-- *********  BL_hip  ********* -->
  <joint name="BL_hip_joint" type="revolute">
    <axis xyz="1 0 0"/>
    <origin rpy="0 0 0" xyz="-0.175 0.066 0"/>
    <parent link="base_link"/>
    <child link="BL_hip_link"/>
    <limit effort="10" lower="-1.57" upper="1.57" velocity="1"/>
    <!-- effort = 7 -->
    <dynamics damping="0.01" friction="10000"/>
  </joint>
  <!-- *********  FR_uleg joint ********* -->
  <joint name="FR_uleg_joint" type="revolute">
    <axis xyz="0 -1 0"/>
    <origin rpy="0 0 0" xyz="0 -0.104 0"/>
    <parent link="FR_hip_link"/>
    <child link="FR_uleg_link"/>
    <limit effort="10" lower="-1.2217" upper="3.14" velocity="1"/>
    <dynamics damping="0.01" friction="10000"/>
  </joint>
  <!-- *********  FL_uleg  ********* -->
  <joint name="FL_uleg_joint" type="revolute">
    <axis xyz="0 -1 0"/>
    <origin rpy="0 0 0" xyz="0 0.104 0"/>
    <parent link="FL_hip_link"/>
    <child link="FL_uleg_link"/>
    <limit effort="10" lower="-1.2217" upper="3.14" velocity="1"/>
    <dynamics damping="0.01" friction="10000"/>
  </joint>
  <!-- *********  BR_uleg  ********* -->
  <joint name="BR_uleg_joint" type="revolute">
    <axis xyz="0 -1 0"/>
    <origin rpy="0 0 0" xyz="0 -0.104 0"/>
    <parent link="BR_hip_link"/>
    <child link="BR_uleg_link"/>
    <limit effort="10" lower="-1.2217" upper="3.14" velocity="1"/>
    <dynamics damping="0.01" friction="10000"/>
  </joint>
  <!-- *********  BL_uleg  ********* -->
  <joint name="BL_uleg_joint" type="revolute">
    <axis xyz="0 -1 0"/>
    <origin rpy="0 0 0" xyz="0 0.104 0"/>
    <parent link="BL_hip_link"/>
    <child link="BL_uleg_link"/>
    <limit effort="10" lower="-1.2217" upper="3.14" velocity="1"/>
    <dynamics damping="0.01" friction="10000"/>
  </joint>
  <!-- *********  FR_lleg  ********* -->
  <joint name="FR_lleg_joint" type="revolute">
    <axis xyz="0 1 0"/>
    <origin rpy="0 0.0 0" xyz="-0.15 0 0"/>
    <parent link="FR_uleg_link"/>
    <child link="FR_lleg_link"/>
    <limit effort="10" lower="-1.57" upper="2.618" velocity="1"/>
    <dynamics damping="0.01" friction="10000"/>
  </joint>
  <!-- *********  FL_lleg  ********* -->
  <joint name="FL_lleg_joint" type="revolute">
    <axis xyz="0 1 0"/>
    <origin rpy="0 0.0 0" xyz="-0.15 0 0"/>
    <parent link="FL_uleg_link"/>
    <child link="FL_lleg_link"/>
    <limit effort="10" lower="-1.57" upper="2.618" velocity="1"/>
    <dynamics damping="0.01" friction="10000"/>
  </joint>
  <!-- *********  BR_lleg  ********* -->
  <joint name="BR_lleg_joint" type="revolute">
    <origin rpy="0 0.0 0" xyz="-0.15 0 0"/>
    <parent link="BR_uleg_link"/>
    <child link="BR_lleg_link"/>
    <axis xyz="0 1 0"/>
    <limit effort="10" lower="-1.57" upper="2.618" velocity="1"/>
    <dynamics damping="0.01" friction="10000"/>
  </joint>
  <!-- *********  BL_lleg  ********* -->
  <joint name="BL_lleg_joint" type="revolute">
    <axis xyz="0 1 0"/>
    <origin rpy="0 0.0 0" xyz="-0.15 0 0"/>
    <parent link="BL_uleg_link"/>
    <child link="BL_lleg_link"/>
    <limit effort="10" lower="-1.57" upper="2.618" velocity="1"/>
    <dynamics damping="0.01" friction="10000"/>
  </joint>
  <!-- *********  FR_FOOT  ********* -->
  <joint name="FR_foot_fixed" type="fixed">
    <origin rpy="0 0 0" xyz="0.14 0 0"/>
    <parent link="FR_lleg_link"/>
    <child link="FR_foot"/>
  </joint>
  <!-- *********  FL_FOOT  ********* -->
  <joint name="FL_foot_fixed" type="fixed">
    <origin rpy="0 0 0" xyz="0.14 0 0"/>
    <parent link="FL_lleg_link"/>
    <child link="FL_foot"/>
  </joint>
  <!-- *********  BR_FOOT  ********* -->
  <joint name="BR_foot_fixed" type="fixed">
    <origin rpy="0 0 0" xyz="0.14 0 0"/>
    <parent link="BR_lleg_link"/>
    <child link="BR_foot"/>
  </joint>
  <!-- *********  BL_FOOT  ********* -->
  <joint name="BL_foot_fixed" type="fixed">
    <origin rpy="0 0 0" xyz="0.14 0 0"/>
    <parent link="BL_lleg_link"/>
    <child link="BL_foot"/>
  </joint>
  <!-- ************* JOINT CONTROLLER GAZEBO PLUGIN ************** -->
  <!-- 
    _____________________________________________________________________
        include this file into: /description/hyperdog.urdf.xacro 
        using following line: 
                    <xacro:include filename="gazebo_ros2_control_plugin.xacro" /> 
    _____________________________________________________________________ -->
  <!-- CONFIGURE JOINTS OF THE ROBOT -->
  <ros2_control name="GazeboSystem" type="System">
    <hardware>
      <plugin>gazebo_ros2_control/GazeboSystem</plugin>
    </hardware>
    <joint name="FR_hip_joint">
      <command_interface name="position">
        <param name="min">-1.57</param>
        <param name="max">1.57</param>
      </command_interface>
      <state_interface name="position">
        <param name="initial_value">0.0</param>
      </state_interface>
      <state_interface name="velocity"/>
      <state_interface name="effort"/>
    </joint>
    <joint name="FR_uleg_joint">
      <command_interface name="position">
        <param name="min">-1.2217</param>
        <param name="max">3.14</param>
      </command_interface>
      <state_interface name="position">
        <param name="initial_value">0.0</param>
      </state_interface>
      <state_interface name="velocity"/>
      <state_interface name="effort"/>
    </joint>
    <joint name="FR_lleg_joint">
      <command_interface name="position">
        <param name="min">0.45</param>
        <param name="max">2.3562</param>
      </command_interface>
      <state_interface name="position">
        <param name="initial_value">0.45</param>
      </state_interface>
      <state_interface name="velocity"/>
      <state_interface name="effort"/>
    </joint>
    <joint name="FL_hip_joint">
      <command_interface name="position">
        <param name="min">-1.57</param>
        <param name="max">1.57</param>
      </command_interface>
      <state_interface name="position">
        <param name="initial_value">0.0</param>
      </state_interface>
      <state_interface name="velocity"/>
      <state_interface name="effort"/>
    </joint>
    <joint name="FL_uleg_joint">
      <command_interface name="position">
        <param name="min">-1.2217</param>
        <param name="max">3.14</param>
      </command_interface>
      <state_interface name="position">
        <param name="initial_value">0.0</param>
      </state_interface>
      <state_interface name="velocity"/>
      <state_interface name="effort"/>
    </joint>
    <joint name="FL_lleg_joint">
      <command_interface name="position">
        <param name="min">0.45</param>
        <param name="max">2.3562</param>
      </command_interface>
      <state_interface name="position">
        <param name="initial_value">0.45</param>
      </state_interface>
      <state_interface name="velocity"/>
      <state_interface name="effort"/>
    </joint>
    <joint name="BR_hip_joint">
      <command_interface name="position">
        <param name="min">-1.57</param>
        <param name="max">1.57</param>
      </command_interface>
      <state_interface name="position">
        <param name="initial_value">0.0</param>
      </state_interface>
      <state_interface name="velocity"/>
      <state_interface name="effort"/>
    </joint>
    <joint name="BR_uleg_joint">
      <command_interface name="position">
        <param name="min">-1.2217</param>
        <param name="max">3.14</param>
      </command_interface>
      <state_interface name="position">
        <param name="initial_value">0.0</param>
      </state_interface>
      <state_interface name="velocity"/>
      <state_interface name="effort"/>
    </joint>
    <joint name="BR_lleg_joint">
      <command_interface name="position">
        <param name="min">0.45</param>
        <param name="max">2.3562</param>
      </command_interface>
      <state_interface name="position">
        <param name="initial_value">0.45</param>
      </state_interface>
      <state_interface name="velocity"/>
      <state_interface name="effort"/>
    </joint>
    <joint name="BL_hip_joint">
      <command_interface name="position">
        <param name="min">-1.57</param>
        <param name="max">1.57</param>
      </command_interface>
      <state_interface name="position">
        <param name="initial_value">0.0</param>
      </state_interface>
      <state_interface name="velocity"/>
      <state_interface name="effort"/>
    </joint>
    <joint name="BL_uleg_joint">
      <command_interface name="position">
        <param name="min">-1.2217</param>
        <param name="max">3.14</param>
      </command_interface>
      <state_interface name="position">
        <param name="initial_value">0.0</param>
      </state_interface>
      <state_interface name="velocity"/>
      <state_interface name="effort"/>
    </joint>
    <joint name="BL_lleg_joint">
      <command_interface name="position">
        <param name="min">0.45</param>
        <param name="max">2.3562</param>
      </command_interface>
      <state_interface name="position">
        <param name="initial_value">0.45</param>
      </state_interface>
      <state_interface name="velocity"/>
      <state_interface name="effort"/>
    </joint>
  </ros2_control>
  <!--  CONFIGURE THE GAZEBO PLUGIN -->
  <gazebo>
    <plugin filename="libgazebo_ros2_control.so" name="gazebo_ros2_control">
      <parameters>/home/vimarsh/Desktop/ROS-Stuff/hyprdog_ws/install/hyperdog_gazebo_sim/share/hyperdog_gazebo_sim/config/hyperdog_joint_controller.yaml</parameters>
    </plugin>
  </gazebo>
  <!--
    _____________________________________________________________________
        include this file into: /description/hyperdog.urdf.xacro 
        using following line: 
                    <xacro:include filename="hyperdog_gazebo.xacro" /> 
    _____________________________________________________________________ 
    * Gazebo is unable to use the same <material> tags that are already in the URDF (that RViz uses).
    Instead, we need to add gazebo tags for our links that refer to Gazebo materials
-->
  <!-- ************************************************************************************************** -->
  <!-- body -->
  <gazebo reference="base_link">
    <mu1>0.05</mu1>
    <mu2>0.05</mu2>
    <!-- <kp>1000000.0</kp>
        <kd>1.0</kd> -->
    <maxVel>0.01</maxVel>
    <material>Gazebo/DarkGrey  </material>
  </gazebo>
  <!-- hip -->
  <gazebo reference="FR_hip_link">
    <mu1>0.2</mu1>
    <mu2>0.2</mu2>
    <kp value="2147483647.0"/>
    <kd value="1.0"/>
    <maxVel>0.01</maxVel>
    <self_collide>1</self_collide>
    <material>Gazebo/PioneerBody</material>
  </gazebo>
  <gazebo reference="FL_hip_link">
    <mu1>0.2</mu1>
    <mu2>0.2</mu2>
    <kp value="2147483647.0"/>
    <kd value="1.0"/>
    <maxVel>0.01</maxVel>
    <self_collide>1</self_collide>
    <material>Gazebo/PioneerBody</material>
  </gazebo>
  <gazebo reference="BR_hip_link">
    <mu1>0.2</mu1>
    <mu2>0.2</mu2>
    <kp value="2147483647.0"/>
    <kd value="1.0"/>
    <maxVel>0.01</maxVel>
    <self_collide>1</self_collide>
    <material>Gazebo/PioneerBody</material>
  </gazebo>
  <gazebo reference="BL_hip_link">
    <mu1>0.2</mu1>
    <mu2>0.2</mu2>
    <kp value="2147483647.0"/>
    <kd value="1.0"/>
    <maxVel>0.01</maxVel>
    <self_collide>1</self_collide>
    <material>Gazebo/PioneerBody</material>
  </gazebo>
  <!-- uleg -->
  <gazebo reference="FR_uleg_link">
    <mu1>0.2</mu1>
    <mu2>0.2</mu2>
    <kp value="2147483647.0"/>
    <kd value="1.0"/>
    <maxVel>0.01</maxVel>
    <self_collide>1</self_collide>
    <material>Gazebo/Orange</material>
    <!-- <implicitSpringDamper>1</implicitSpringDamper>
        <springStiffness>100</springStiffness> -->
  </gazebo>
  <gazebo reference="FL_uleg_link">
    <mu1>0.2</mu1>
    <mu2>0.2</mu2>
    <kp value="2147483647.0"/>
    <kd value="1.0"/>
    <maxVel>0.01</maxVel>
    <self_collide>1</self_collide>
    <material>Gazebo/Orange</material>
    <!-- <implicitSpringDamper>1</implicitSpringDamper>
        <springStiffness>100</springStiffness> -->
  </gazebo>
  <gazebo reference="BR_uleg_link">
    <mu1>0.2</mu1>
    <mu2>0.2</mu2>
    <kp value="2147483647.0"/>
    <kd value="1.0"/>
    <maxVel>0.01</maxVel>
    <self_collide>1</self_collide>
    <material>Gazebo/Orange</material>
    <!-- <implicitSpringDamper>1</implicitSpringDamper>
        <springStiffness>100</springStiffness> -->
  </gazebo>
  <gazebo reference="BL_uleg_link">
    <mu1>0.2</mu1>
    <mu2>0.2</mu2>
    <kp value="2147483647.0"/>
    <kd value="1.0"/>
    <maxVel>0.01</maxVel>
    <self_collide>1</self_collide>
    <material>Gazebo/Orange</material>
    <!-- <implicitSpringDamper>1</implicitSpringDamper>
        <springStiffness>100</springStiffness> -->
  </gazebo>
  <!-- lleg -->
  <gazebo reference="FR_lleg_link">
    <mu1>0.2</mu1>
    <mu2>0.2</mu2>
    <fdir1>1 0 0</fdir1>
    <kp>2147483647.0</kp>
    <kd>1.0</kd>
    <maxVel>0.01</maxVel>
    <self_collide>1</self_collide>
    <material>Gazebo/DarkYellow</material>
    <minDepth>0.001</minDepth>
    <!-- <implicitSpringDamper>1</implicitSpringDamper>
        <springStiffness>100</springStiffness> -->
  </gazebo>
  <gazebo reference="FL_lleg_link">
    <mu1>0.2</mu1>
    <mu2>0.2</mu2>
    <fdir1>1 0 0</fdir1>
    <kp>2147483647.0</kp>
    <kd>1.0</kd>
    <maxVel>0.01</maxVel>
    <self_collide>1</self_collide>
    <material>Gazebo/DarkYellow</material>
    <minDepth>0.001</minDepth>
    <!-- <implicitSpringDamper>1</implicitSpringDamper>
        <springStiffness>100</springStiffness> -->
  </gazebo>
  <gazebo reference="BR_lleg_link">
    <mu1>0.2</mu1>
    <mu2>0.2</mu2>
    <fdir1>1 0 0</fdir1>
    <kp>2147483647.0</kp>
    <kd>1.0</kd>
    <maxVel>0.01</maxVel>
    <self_collide>1</self_collide>
    <material>Gazebo/DarkYellow</material>
    <minDepth>0.001</minDepth>
    <!-- <implicitSpringDamper>1</implicitSpringDamper>
        <springStiffness>100</springStiffness> -->
  </gazebo>
  <gazebo reference="BL_lleg_link">
    <mu1>0.2</mu1>
    <mu2>0.2</mu2>
    <fdir1>1 0 0</fdir1>
    <kp>2147483647.0</kp>
    <kd>1.0</kd>
    <maxVel>0.01</maxVel>
    <self_collide>1</self_collide>
    <material>Gazebo/DarkYellow</material>
    <minDepth>0.001</minDepth>
    <!-- <implicitSpringDamper>1</implicitSpringDamper>
        <springStiffness>100</springStiffness> -->
  </gazebo>
  <!-- feet -->
  <gazebo reference="FR_foot">
    <mu1>0.9</mu1>
    <mu2>0.9</mu2>
    <fdir1>1 1 0</fdir1>
    <kp value="2147483647.0"/>
    <kd value="100.0"/>
    <maxVel>0.01</maxVel>
    <self_collide>1</self_collide>
    <minDepth>0.001</minDepth>
    <restitution_coefficient>1</restitution_coefficient>
    <threshold>0</threshold>
    <material>Gazebo/DarkGrey</material>
  </gazebo>
  <gazebo reference="FL_foot">
    <mu1>0.9</mu1>
    <mu2>0.9</mu2>
    <fdir1>1 1 0</fdir1>
    <kp value="2147483647.0"/>
    <kd value="100.0"/>
    <maxVel>0.01</maxVel>
    <self_collide>1</self_collide>
    <minDepth>0.001</minDepth>
    <restitution_coefficient>1</restitution_coefficient>
    <threshold>0</threshold>
    <material>Gazebo/DarkGrey</material>
  </gazebo>
  <gazebo reference="BL_foot">
    <mu1>0.9</mu1>
    <mu2>0.9</mu2>
    <fdir1>1 1 0</fdir1>
    <kp value="2147483647.0"/>
    <kd value="100.0"/>
    <maxVel>0.01</maxVel>
    <self_collide>1</self_collide>
    <minDepth>0.001</minDepth>
    <restitution_coefficient>1</restitution_coefficient>
    <threshold>0</threshold>
    <material>Gazebo/DarkGrey</material>
  </gazebo>
  <gazebo reference="BR_foot">
    <mu1>0.9</mu1>
    <mu2>0.9</mu2>
    <fdir1>1 1 0</fdir1>
    <kp value="2147483647.0"/>
    <kd value="100.0"/>
    <maxVel>0.01</maxVel>
    <self_collide>1</self_collide>
    <minDepth>0.001</minDepth>
    <restitution_coefficient>1</restitution_coefficient>
    <threshold>0</threshold>
    <material>Gazebo/DarkGrey</material>
  </gazebo>
</robot>
